2022-12-27 01:08:06,497:streamlit_frontend.py:run:INFO:Session started:
2022-12-27 01:08:18,903:streamlit_frontend.py:run:INFO:Session started:
2022-12-27 01:08:18,922:streamlit_frontend.py:run:INFO:User data uploaded:
2022-12-27 01:08:31,492:streamlit_frontend.py:run:INFO:Session started:
2022-12-27 01:08:31,504:streamlit_frontend.py:run:INFO:User data uploaded:
2022-12-27 01:08:31,538:streamlit_frontend.py:run:INFO:Attempting API call:
2022-12-27 01:08:32,047:streamlit_frontend.py:run:INFO:Prediction successful, 
Model used: Logistic Regression, 
Credit Card Default probability: 15.774575000930366, 
Model pred time: 0.005196400001295842, 
total run time: 0.5027285000032862:
2022-12-27 01:09:24,551:streamlit_frontend.py:run:INFO:Session started:
2022-12-27 01:09:25,153:streamlit_frontend.py:run:INFO:Session started:
2022-12-27 01:09:25,185:streamlit_frontend.py:run:INFO:User data uploaded:
2022-12-27 01:09:30,259:streamlit_frontend.py:run:INFO:Session started:
2022-12-27 01:09:30,278:streamlit_frontend.py:run:INFO:User data uploaded:
2022-12-27 01:09:32,339:streamlit_frontend.py:run:INFO:Session started:
2022-12-27 01:09:32,358:streamlit_frontend.py:run:INFO:User data uploaded:
2022-12-27 01:09:34,171:streamlit_frontend.py:run:INFO:Attempting API call:
2022-12-27 01:09:39,157:streamlit_frontend.py:run:ERROR:An error occurred whilst attempting to call API:
Traceback (most recent call last):
  File "C:\Users\Abraham Audu\Documents\Py-Self-Learn\credit_card_default_prediction\venv\lib\site-packages\requests\models.py", line 971, in json
    return complexjson.loads(self.text, **kwargs)
  File "C:\Program Files\python310\lib\json\__init__.py", line 346, in loads
    return _default_decoder.decode(s)
  File "C:\Program Files\python310\lib\json\decoder.py", line 337, in decode
    obj, end = self.raw_decode(s, idx=_w(s, 0).end())
  File "C:\Program Files\python310\lib\json\decoder.py", line 355, in raw_decode
    raise JSONDecodeError("Expecting value", s, err.value) from None
json.decoder.JSONDecodeError: Expecting value: line 1 column 1 (char 0)

During handling of the above exception, another exception occurred:

Traceback (most recent call last):
  File "C:\Users\Abraham Audu\Documents\Py-Self-Learn\credit_card_default_prediction\src\streamlit_frontend.py", line 56, in run
    response = requests.post("http://127.0.0.1:8000/predict", json=data).json()
  File "C:\Users\Abraham Audu\Documents\Py-Self-Learn\credit_card_default_prediction\venv\lib\site-packages\requests\models.py", line 975, in json
    raise RequestsJSONDecodeError(e.msg, e.doc, e.pos)
requests.exceptions.JSONDecodeError: Expecting value: line 1 column 1 (char 0)
2022-12-27 01:18:02,855:streamlit_frontend.py:run:INFO:Session started:
2022-12-27 01:18:02,876:streamlit_frontend.py:run:INFO:User data uploaded:
2022-12-27 01:18:04,748:streamlit_frontend.py:run:INFO:Attempting API call:
2022-12-27 01:18:11,753:streamlit_frontend.py:run:ERROR:An error occurred whilst attempting to call API:
Traceback (most recent call last):
  File "C:\Users\Abraham Audu\Documents\Py-Self-Learn\credit_card_default_prediction\venv\lib\site-packages\requests\models.py", line 971, in json
    return complexjson.loads(self.text, **kwargs)
  File "C:\Program Files\python310\lib\json\__init__.py", line 346, in loads
    return _default_decoder.decode(s)
  File "C:\Program Files\python310\lib\json\decoder.py", line 337, in decode
    obj, end = self.raw_decode(s, idx=_w(s, 0).end())
  File "C:\Program Files\python310\lib\json\decoder.py", line 355, in raw_decode
    raise JSONDecodeError("Expecting value", s, err.value) from None
json.decoder.JSONDecodeError: Expecting value: line 1 column 1 (char 0)

During handling of the above exception, another exception occurred:

Traceback (most recent call last):
  File "C:\Users\Abraham Audu\Documents\Py-Self-Learn\credit_card_default_prediction\src\streamlit_frontend.py", line 56, in run
    response = requests.post("http://127.0.0.1:8000/predict", json=data).json()
  File "C:\Users\Abraham Audu\Documents\Py-Self-Learn\credit_card_default_prediction\venv\lib\site-packages\requests\models.py", line 975, in json
    raise RequestsJSONDecodeError(e.msg, e.doc, e.pos)
requests.exceptions.JSONDecodeError: Expecting value: line 1 column 1 (char 0)
2022-12-27 17:54:18,748:streamlit_frontend.py:run:INFO:Session started:
2022-12-27 17:55:48,656:streamlit_frontend.py:run:INFO:Session started:
2022-12-27 17:56:08,911:streamlit_frontend.py:run:INFO:Session started:
2022-12-27 17:56:08,928:streamlit_frontend.py:run:INFO:User data uploaded:
2022-12-27 17:58:41,701:streamlit_frontend.py:run:INFO:Session started:
2022-12-27 17:58:52,417:streamlit_frontend.py:run:INFO:Session started:
2022-12-27 17:58:52,440:streamlit_frontend.py:run:INFO:User data uploaded:
2022-12-27 17:58:52,475:streamlit_frontend.py:run:INFO:Uploaded data validated:
2022-12-27 17:59:01,689:streamlit_frontend.py:run:INFO:Session started:
2022-12-27 17:59:02,158:streamlit_frontend.py:run:INFO:Session started:
2022-12-27 17:59:02,176:streamlit_frontend.py:run:INFO:User data uploaded:
2022-12-27 17:59:02,565:upload_validator.py:validate:ERROR:Column 'default.payment.next.month' not expected in uploaded data:
2022-12-27 18:02:05,557:streamlit_frontend.py:run:INFO:Session started:
2022-12-27 18:02:05,579:streamlit_frontend.py:run:INFO:User data uploaded:
2022-12-27 18:02:05,962:upload_validator.py:validate:ERROR:Column 'default.payment.next.month' not expected in uploaded data:
2022-12-27 18:02:07,585:streamlit_frontend.py:run:INFO:Attempting API call:
2022-12-27 18:02:12,980:streamlit_frontend.py:run:ERROR:An error occurred whilst attempting to call API:
Traceback (most recent call last):
  File "C:\Users\Abraham Audu\Documents\Py-Self-Learn\credit_card_default_prediction\venv\lib\site-packages\requests\models.py", line 971, in json
    return complexjson.loads(self.text, **kwargs)
  File "C:\Program Files\python310\lib\json\__init__.py", line 346, in loads
    return _default_decoder.decode(s)
  File "C:\Program Files\python310\lib\json\decoder.py", line 337, in decode
    obj, end = self.raw_decode(s, idx=_w(s, 0).end())
  File "C:\Program Files\python310\lib\json\decoder.py", line 355, in raw_decode
    raise JSONDecodeError("Expecting value", s, err.value) from None
json.decoder.JSONDecodeError: Expecting value: line 1 column 1 (char 0)

During handling of the above exception, another exception occurred:

Traceback (most recent call last):
  File "C:\Users\Abraham Audu\Documents\Py-Self-Learn\credit_card_default_prediction\src\streamlit_frontend.py", line 64, in run
    response = requests.post("http://127.0.0.1:8000/predict", json=data).json()
  File "C:\Users\Abraham Audu\Documents\Py-Self-Learn\credit_card_default_prediction\venv\lib\site-packages\requests\models.py", line 975, in json
    raise RequestsJSONDecodeError(e.msg, e.doc, e.pos)
requests.exceptions.JSONDecodeError: Expecting value: line 1 column 1 (char 0)
2022-12-27 18:05:21,427:streamlit_frontend.py:run:INFO:Session started:
2022-12-27 18:06:16,497:streamlit_frontend.py:run:INFO:Session started:
2022-12-27 18:06:30,156:streamlit_frontend.py:run:INFO:Session started:
2022-12-27 18:06:30,176:streamlit_frontend.py:run:INFO:User data uploaded:
2022-12-27 18:06:30,517:upload_validator.py:validate:ERROR:Column 'default.payment.next.month' not expected in uploaded data:
2022-12-27 18:06:44,337:streamlit_frontend.py:run:INFO:Session started:
2022-12-27 18:06:44,643:streamlit_frontend.py:run:INFO:Session started:
2022-12-27 18:06:44,662:streamlit_frontend.py:run:INFO:User data uploaded:
2022-12-27 18:06:44,690:streamlit_frontend.py:run:INFO:Uploaded data validated:
2022-12-27 18:06:57,793:streamlit_frontend.py:run:INFO:Session started:
2022-12-27 18:06:58,150:streamlit_frontend.py:run:INFO:Session started:
2022-12-27 18:06:58,169:streamlit_frontend.py:run:INFO:User data uploaded:
2022-12-27 18:06:58,580:upload_validator.py:validate:ERROR:Column 'default.payment.next.month' not expected in uploaded data:
2023-02-01 12:09:49,724:streamlit_frontend.py:run:INFO:Session started:
2023-02-01 12:10:45,788:streamlit_frontend.py:run:INFO:Session started:
2023-02-01 12:10:45,794:streamlit_frontend.py:run:INFO:User data uploaded:
2023-02-01 12:10:45,882:streamlit_frontend.py:run:INFO:Uploaded data validated:
2023-02-01 12:11:17,330:streamlit_frontend.py:run:INFO:Session started:
2023-02-01 12:11:17,336:streamlit_frontend.py:run:INFO:User data uploaded:
2023-02-01 12:11:17,342:streamlit_frontend.py:run:INFO:Uploaded data validated:
2023-02-01 12:11:32,337:streamlit_frontend.py:run:INFO:Session started:
2023-02-01 12:11:32,344:streamlit_frontend.py:run:INFO:User data uploaded:
2023-02-01 12:11:32,352:streamlit_frontend.py:run:INFO:Uploaded data validated:
2023-02-01 12:11:32,357:streamlit_frontend.py:run:INFO:Attempting API call:
2023-02-01 12:11:32,551:streamlit_frontend.py:run:ERROR:An error occurred whilst attempting to call API:
Traceback (most recent call last):
  File "C:\Users\Abraham Audu\Documents\Py-Self-Learn\credit_card_default_prediction\venv\lib\site-packages\requests\models.py", line 971, in json
    return complexjson.loads(self.text, **kwargs)
  File "C:\Program Files\python310\lib\json\__init__.py", line 346, in loads
    return _default_decoder.decode(s)
  File "C:\Program Files\python310\lib\json\decoder.py", line 337, in decode
    obj, end = self.raw_decode(s, idx=_w(s, 0).end())
  File "C:\Program Files\python310\lib\json\decoder.py", line 355, in raw_decode
    raise JSONDecodeError("Expecting value", s, err.value) from None
json.decoder.JSONDecodeError: Expecting value: line 1 column 1 (char 0)

During handling of the above exception, another exception occurred:

Traceback (most recent call last):
  File "C:\Users\Abraham Audu\Documents\Py-Self-Learn\credit_card_default_prediction\src\streamlit_frontend.py", line 67, in run
    response = requests.post("http://127.0.0.1:8000/predict", json=data).json()
  File "C:\Users\Abraham Audu\Documents\Py-Self-Learn\credit_card_default_prediction\venv\lib\site-packages\requests\models.py", line 975, in json
    raise RequestsJSONDecodeError(e.msg, e.doc, e.pos)
requests.exceptions.JSONDecodeError: Expecting value: line 1 column 1 (char 0)
2023-02-01 12:13:26,186:streamlit_frontend.py:run:INFO:Session started:
2023-02-01 12:13:26,349:streamlit_frontend.py:run:INFO:Session started:
2023-02-01 12:13:26,353:streamlit_frontend.py:run:INFO:User data uploaded:
2023-02-01 12:13:26,451:upload_validator.py:validate:ERROR:Column 'default.payment.next.month' not expected in uploaded data:
2023-07-13 16:50:55,899:streamlit_frontend.py:run:INFO:Session started:
2023-07-13 16:51:50,518:streamlit_frontend.py:run:INFO:Session started:
2023-07-13 16:51:50,528:streamlit_frontend.py:run:INFO:User data uploaded:
2023-07-13 16:51:50,578:streamlit_frontend.py:run:INFO:Uploaded data validated:
2023-07-13 16:52:02,019:streamlit_frontend.py:run:INFO:Session started:
2023-07-13 16:52:02,030:streamlit_frontend.py:run:INFO:User data uploaded:
2023-07-13 16:52:02,046:streamlit_frontend.py:run:INFO:Uploaded data validated:
2023-07-13 16:52:11,982:streamlit_frontend.py:run:INFO:Session started:
2023-07-13 16:52:11,993:streamlit_frontend.py:run:INFO:User data uploaded:
2023-07-13 16:52:12,013:streamlit_frontend.py:run:INFO:Uploaded data validated:
2023-07-13 16:53:19,866:streamlit_frontend.py:run:INFO:Session started:
2023-07-13 16:53:19,874:streamlit_frontend.py:run:INFO:User data uploaded:
2023-07-13 16:53:19,888:streamlit_frontend.py:run:INFO:Uploaded data validated:
2023-07-13 16:53:19,893:streamlit_frontend.py:run:INFO:Attempting API call:
2023-07-13 16:53:20,108:streamlit_frontend.py:run:ERROR:An error occurred whilst attempting to call API:
Traceback (most recent call last):
  File "C:\Users\Abraham Audu\Documents\Py-Self-Learn\credit_card_default_prediction\venv\lib\site-packages\requests\models.py", line 971, in json
    return complexjson.loads(self.text, **kwargs)
  File "C:\Program Files\python310\lib\json\__init__.py", line 346, in loads
    return _default_decoder.decode(s)
  File "C:\Program Files\python310\lib\json\decoder.py", line 337, in decode
    obj, end = self.raw_decode(s, idx=_w(s, 0).end())
  File "C:\Program Files\python310\lib\json\decoder.py", line 355, in raw_decode
    raise JSONDecodeError("Expecting value", s, err.value) from None
json.decoder.JSONDecodeError: Expecting value: line 1 column 1 (char 0)

During handling of the above exception, another exception occurred:

Traceback (most recent call last):
  File "C:\Users\Abraham Audu\Documents\Py-Self-Learn\credit_card_default_prediction\src\streamlit_frontend.py", line 68, in run
    response = requests.post("http://127.0.0.1:8000/predict", json=data).json()
  File "C:\Users\Abraham Audu\Documents\Py-Self-Learn\credit_card_default_prediction\venv\lib\site-packages\requests\models.py", line 975, in json
    raise RequestsJSONDecodeError(e.msg, e.doc, e.pos)
requests.exceptions.JSONDecodeError: Expecting value: line 1 column 1 (char 0)
2023-07-13 16:57:20,299:streamlit_frontend.py:run:INFO:Session started:
2023-07-13 16:57:20,307:streamlit_frontend.py:run:INFO:User data uploaded:
2023-07-13 16:57:20,326:streamlit_frontend.py:run:INFO:Uploaded data validated:
2023-07-13 16:57:20,332:streamlit_frontend.py:run:INFO:Attempting API call:
2023-07-13 16:57:20,451:streamlit_frontend.py:run:ERROR:An error occurred whilst attempting to call API:
Traceback (most recent call last):
  File "C:\Users\Abraham Audu\Documents\Py-Self-Learn\credit_card_default_prediction\venv\lib\site-packages\requests\models.py", line 971, in json
    return complexjson.loads(self.text, **kwargs)
  File "C:\Program Files\python310\lib\json\__init__.py", line 346, in loads
    return _default_decoder.decode(s)
  File "C:\Program Files\python310\lib\json\decoder.py", line 337, in decode
    obj, end = self.raw_decode(s, idx=_w(s, 0).end())
  File "C:\Program Files\python310\lib\json\decoder.py", line 355, in raw_decode
    raise JSONDecodeError("Expecting value", s, err.value) from None
json.decoder.JSONDecodeError: Expecting value: line 1 column 1 (char 0)

During handling of the above exception, another exception occurred:

Traceback (most recent call last):
  File "C:\Users\Abraham Audu\Documents\Py-Self-Learn\credit_card_default_prediction\src\streamlit_frontend.py", line 68, in run
    response = requests.post("http://127.0.0.1:8000/predict", json=data).json()
  File "C:\Users\Abraham Audu\Documents\Py-Self-Learn\credit_card_default_prediction\venv\lib\site-packages\requests\models.py", line 975, in json
    raise RequestsJSONDecodeError(e.msg, e.doc, e.pos)
requests.exceptions.JSONDecodeError: Expecting value: line 1 column 1 (char 0)
2023-07-13 16:57:28,220:streamlit_frontend.py:run:INFO:Session started:
2023-07-13 16:57:28,233:streamlit_frontend.py:run:INFO:User data uploaded:
2023-07-13 16:57:28,250:streamlit_frontend.py:run:INFO:Uploaded data validated:
2023-07-13 16:57:28,255:streamlit_frontend.py:run:INFO:Attempting API call:
2023-07-13 16:57:28,298:streamlit_frontend.py:run:ERROR:An error occurred whilst attempting to call API:
Traceback (most recent call last):
  File "C:\Users\Abraham Audu\Documents\Py-Self-Learn\credit_card_default_prediction\venv\lib\site-packages\requests\models.py", line 971, in json
    return complexjson.loads(self.text, **kwargs)
  File "C:\Program Files\python310\lib\json\__init__.py", line 346, in loads
    return _default_decoder.decode(s)
  File "C:\Program Files\python310\lib\json\decoder.py", line 337, in decode
    obj, end = self.raw_decode(s, idx=_w(s, 0).end())
  File "C:\Program Files\python310\lib\json\decoder.py", line 355, in raw_decode
    raise JSONDecodeError("Expecting value", s, err.value) from None
json.decoder.JSONDecodeError: Expecting value: line 1 column 1 (char 0)

During handling of the above exception, another exception occurred:

Traceback (most recent call last):
  File "C:\Users\Abraham Audu\Documents\Py-Self-Learn\credit_card_default_prediction\src\streamlit_frontend.py", line 68, in run
    response = requests.post("http://127.0.0.1:8000/predict", json=data).json()
  File "C:\Users\Abraham Audu\Documents\Py-Self-Learn\credit_card_default_prediction\venv\lib\site-packages\requests\models.py", line 975, in json
    raise RequestsJSONDecodeError(e.msg, e.doc, e.pos)
requests.exceptions.JSONDecodeError: Expecting value: line 1 column 1 (char 0)
